<?xml version="1.0"?>
<sdf version="1.4">
  <model name="caroca">
    <!--Definition of the robot frame-->
    <link name="frame">
      <pose>0 0 0 0 0 0</pose>
      <inertial>
        <inertia>
          <ixx>100000</ixx>
          <iyy>100000</iyy>
          <izz>100000</izz>
          <ixy>0</ixy>
          <ixz>0</ixz>
          <iyz>0</iyz>
        </inertia>
        <mass>100000</mass>
      </inertial>
      <visual name="visual1">
        <geometry>
          <cylinder>
            <radius>0.02</radius>
            <length>3.48</length>
          </cylinder>
        </geometry>
        <pose>-4.000000 -4.000000 1.760000 0.000000 0.000000 0.000000</pose>
        <material>
          <script>
            <uri>file://media/materials/scripts/kitchen.material</uri>
            <name>Gazebo/Grey</name>
          </script>
        </material>
      </visual>
      <collision name="collision1">
        <geometry>
          <cylinder>
            <radius>0.02</radius>
          </cylinder>
        </geometry>
        <pose>-4.000000 -4.000000 1.760000 0.000000 0.000000 0.000000</pose>
      </collision>
      <visual name="visual2">
        <geometry>
          <cylinder>
            <radius>0.02</radius>
            <length>8.0</length>
          </cylinder>
        </geometry>
        <pose>-4.000000 0.000000 0.020000 1.570796 0.000000 0.000000</pose>
        <material>
          <script>
            <uri>file://media/materials/scripts/kitchen.material</uri>
            <name>Gazebo/Grey</name>
          </script>
        </material>
      </visual>
      <collision name="collision2">
        <geometry>
          <cylinder>
            <radius>0.02</radius>
          </cylinder>
        </geometry>
        <pose>-4.000000 0.000000 0.020000 1.570796 0.000000 0.000000</pose>
      </collision>
      <visual name="visual3">
        <geometry>
          <cylinder>
            <radius>0.02</radius>
            <length>8.0</length>
          </cylinder>
        </geometry>
        <pose>0.000000 -4.000000 0.020000 0.000000 1.570796 0.000000</pose>
        <material>
          <script>
            <uri>file://media/materials/scripts/kitchen.material</uri>
            <name>Gazebo/Grey</name>
          </script>
        </material>
      </visual>
      <collision name="collision3">
        <geometry>
          <cylinder>
            <radius>0.02</radius>
          </cylinder>
        </geometry>
        <pose>0.000000 -4.000000 0.020000 0.000000 1.570796 0.000000</pose>
      </collision>
      <visual name="visual4">
        <geometry>
          <cylinder>
            <radius>0.02</radius>
            <length>8.0</length>
          </cylinder>
        </geometry>
        <pose>-4.000000 0.000000 3.500000 1.570796 0.000000 0.000000</pose>
        <material>
          <script>
            <uri>file://media/materials/scripts/kitchen.material</uri>
            <name>Gazebo/Grey</name>
          </script>
        </material>
      </visual>
      <collision name="collision4">
        <geometry>
          <cylinder>
            <radius>0.02</radius>
          </cylinder>
        </geometry>
        <pose>-4.000000 0.000000 3.500000 1.570796 0.000000 0.000000</pose>
      </collision>
      <visual name="visual5">
        <geometry>
          <cylinder>
            <radius>0.02</radius>
            <length>8.0</length>
          </cylinder>
        </geometry>
        <pose>0.000000 -4.000000 3.500000 0.000000 1.570796 0.000000</pose>
        <material>
          <script>
            <uri>file://media/materials/scripts/kitchen.material</uri>
            <name>Gazebo/Grey</name>
          </script>
        </material>
      </visual>
      <collision name="collision5">
        <geometry>
          <cylinder>
            <radius>0.02</radius>
          </cylinder>
        </geometry>
        <pose>0.000000 -4.000000 3.500000 0.000000 1.570796 0.000000</pose>
      </collision>
      <visual name="visual6">
        <geometry>
          <cylinder>
            <radius>0.02</radius>
            <length>3.48</length>
          </cylinder>
        </geometry>
        <pose>-4.000000 4.000000 1.760000 0.000000 0.000000 0.000000</pose>
        <material>
          <script>
            <uri>file://media/materials/scripts/kitchen.material</uri>
            <name>Gazebo/Grey</name>
          </script>
        </material>
      </visual>
      <collision name="collision6">
        <geometry>
          <cylinder>
            <radius>0.02</radius>
          </cylinder>
        </geometry>
        <pose>-4.000000 4.000000 1.760000 0.000000 0.000000 0.000000</pose>
      </collision>
      <visual name="visual7">
        <geometry>
          <cylinder>
            <radius>0.02</radius>
            <length>8.0</length>
          </cylinder>
        </geometry>
        <pose>0.000000 4.000000 0.020000 0.000000 1.570796 0.000000</pose>
        <material>
          <script>
            <uri>file://media/materials/scripts/kitchen.material</uri>
            <name>Gazebo/Grey</name>
          </script>
        </material>
      </visual>
      <collision name="collision7">
        <geometry>
          <cylinder>
            <radius>0.02</radius>
          </cylinder>
        </geometry>
        <pose>0.000000 4.000000 0.020000 0.000000 1.570796 0.000000</pose>
      </collision>
      <visual name="visual8">
        <geometry>
          <cylinder>
            <radius>0.02</radius>
            <length>8.0</length>
          </cylinder>
        </geometry>
        <pose>0.000000 4.000000 3.500000 0.000000 1.570796 0.000000</pose>
        <material>
          <script>
            <uri>file://media/materials/scripts/kitchen.material</uri>
            <name>Gazebo/Grey</name>
          </script>
        </material>
      </visual>
      <collision name="collision8">
        <geometry>
          <cylinder>
            <radius>0.02</radius>
          </cylinder>
        </geometry>
        <pose>0.000000 4.000000 3.500000 0.000000 1.570796 0.000000</pose>
      </collision>
      <visual name="visual9">
        <geometry>
          <cylinder>
            <radius>0.02</radius>
            <length>3.48</length>
          </cylinder>
        </geometry>
        <pose>4.000000 -4.000000 1.760000 0.000000 0.000000 0.000000</pose>
        <material>
          <script>
            <uri>file://media/materials/scripts/kitchen.material</uri>
            <name>Gazebo/Grey</name>
          </script>
        </material>
      </visual>
      <collision name="collision9">
        <geometry>
          <cylinder>
            <radius>0.02</radius>
          </cylinder>
        </geometry>
        <pose>4.000000 -4.000000 1.760000 0.000000 0.000000 0.000000</pose>
      </collision>
      <visual name="visual10">
        <geometry>
          <cylinder>
            <radius>0.02</radius>
            <length>8.0</length>
          </cylinder>
        </geometry>
        <pose>4.000000 0.000000 0.020000 1.570796 0.000000 0.000000</pose>
        <material>
          <script>
            <uri>file://media/materials/scripts/kitchen.material</uri>
            <name>Gazebo/Grey</name>
          </script>
        </material>
      </visual>
      <collision name="collision10">
        <geometry>
          <cylinder>
            <radius>0.02</radius>
          </cylinder>
        </geometry>
        <pose>4.000000 0.000000 0.020000 1.570796 0.000000 0.000000</pose>
      </collision>
      <visual name="visual11">
        <geometry>
          <cylinder>
            <radius>0.02</radius>
            <length>8.0</length>
          </cylinder>
        </geometry>
        <pose>4.000000 0.000000 3.500000 1.570796 0.000000 0.000000</pose>
        <material>
          <script>
            <uri>file://media/materials/scripts/kitchen.material</uri>
            <name>Gazebo/Grey</name>
          </script>
        </material>
      </visual>
      <collision name="collision11">
        <geometry>
          <cylinder>
            <radius>0.02</radius>
          </cylinder>
        </geometry>
        <pose>4.000000 0.000000 3.500000 1.570796 0.000000 0.000000</pose>
      </collision>
      <visual name="visual12">
        <geometry>
          <cylinder>
            <radius>0.02</radius>
            <length>3.48</length>
          </cylinder>
        </geometry>
        <pose>4.000000 4.000000 1.760000 0.000000 0.000000 0.000000</pose>
        <material>
          <script>
            <uri>file://media/materials/scripts/kitchen.material</uri>
            <name>Gazebo/Grey</name>
          </script>
        </material>
      </visual>
      <collision name="collision12">
        <geometry>
          <cylinder>
            <radius>0.02</radius>
          </cylinder>
        </geometry>
        <pose>4.000000 4.000000 1.760000 0.000000 0.000000 0.000000</pose>
      </collision>
    </link>
    <!--Definition of the robot cables-->
    <!--Definition of the robot platform-->
    <link name="platform">
      <pose>0.000000 0.000000 0.600000 0.000000 0.000000 0.000000</pose>
      <visual name="visualpf">
        <geometry>
          <box>
            <size>0.600000 0.600000 0.600000</size>
          </box>
        </geometry>
        <material>
          <script>
            <uri>file://media/materials/scripts/kitchen.material</uri>
            <name>Gazebo/Blue</name>
          </script>
        </material>
      </visual>
      <collision name="collisionpf">
        <geometry>
          <box>
            <size>0.600000 0.600000 0.600000</size>
          </box>
        </geometry>
      </collision>
      <inertial>
        <inertia>
          <ixx>6.5</ixx>
          <iyy>20.0</iyy>
          <izz>22.5</izz>
          <ixy>0.0</ixy>
          <ixz>0.0</ixz>
          <iyz>0.0</iyz>
        </inertia>
        <mass>150</mass>
      </inertial>
    </link>

  
    <link name="right_grip">
      <pose>0.3 0 0.15 0 0 0</pose>
      <visual name="visual_right_grip">
        <geometry>
          <box>
            <size>0.05 0.6 0.3</size>
          </box>
        </geometry>
        <material>
          <script>
            <uri>file://media/materials/scripts/kitchen.material</uri>
            <name>Gazebo/Blue</name>
          </script>
        </material>
      </visual>
      <collision name="collision_right_grip">
        <geometry>
          <box>
            <size>0.05 0.6 0.3</size>
          </box>
        </geometry>
        <surface>
          <friction>
            <ode>
              <mu>1</mu>
              <mu2>1</mu2>
              <fdir1>0 0 0</fdir1>
              <slip1>0</slip1>
              <slip2>0</slip2>
            </ode>
            <torsional>
              <coefficient>1</coefficient>
              <patch_radius>0</patch_radius>
              <surface_radius>0</surface_radius>
              <use_patch_radius>1</use_patch_radius>
              <ode>
                <slip>0</slip>
              </ode>
            </torsional>
          </friction>
        </surface>
      </collision>
      <inertial>
        <inertia>
          <ixx>0.166667</ixx>
          <iyy>0</iyy>
          <izz>0</izz>
          <ixy>0.166667</ixy>
          <ixz>0</ixz>
          <iyz>0.166667</iyz>
        </inertia>
        <mass>1</mass>
      </inertial>
    </link>

    <link name="left_grip">
      <pose>-0.3 0 0.15 0 0 0</pose>
      <visual name="visual_left_grip">
        <geometry>
          <box>
            <size>0.05 0.6 0.3</size>
          </box>
        </geometry>
        <material>
          <script>
            <uri>file://media/materials/scripts/kitchen.material</uri>
            <name>Gazebo/Blue</name>
          </script>
        </material>
      </visual>
      <collision name="collision_left_grip">
        <geometry>
          <box>
            <size>0.05 0.6 0.3</size>
          </box>
        </geometry>
        <surface>
          <friction>
            <ode>
              <mu>1</mu>
              <mu2>1</mu2>
              <fdir1>0 0 0</fdir1>
              <slip1>0</slip1>
              <slip2>0</slip2>
            </ode>
            <torsional>
              <coefficient>1</coefficient>
              <patch_radius>0</patch_radius>
              <surface_radius>0</surface_radius>
              <use_patch_radius>1</use_patch_radius>
              <ode>
                <slip>0</slip>
              </ode>
            </torsional>
          </friction>
          </surface>
      </collision>
      <inertial>
        <inertia>
          <ixx>0.166667</ixx>
          <iyy>0</iyy>
          <izz>0</izz>
          <ixy>0.166667</ixy>
          <ixz>0</ixz>
          <iyz>0.166667</iyz>
        </inertia>
        <mass>1</mass>
      </inertial>
    </link>

     <joint name="grip_left_slide" type="prismatic">
      <pose>0 0 0 0 0 0</pose>
      <parent>platform</parent>
      <child>left_grip</child>
      <axis>
        <xyz>1 0 0</xyz>
        <limit>
          <lower>0</lower>
          <upper>0.2</upper>
          <effort>1000</effort>
          <velocity>10</velocity>
        </limit>
        <dynamics>
          <spring_reference>0</spring_reference>
          <spring_stiffness>0</spring_stiffness>
          <damping>0</damping>
        </dynamics>
      </axis>
    </joint>


    <joint name="grip_right_slide" type="prismatic">
      <pose>0 0 0 0 0 0</pose>
      <parent>platform</parent>
      <child>right_grip</child>
      <axis>
        <xyz>-1 0 0</xyz>
        <limit>
           <lower>0</lower>
          <upper>0.2</upper>
          <effort>1000</effort>
          <velocity>10</velocity>
        </limit>
        <dynamics>
          <spring_reference>0</spring_reference>
          <spring_stiffness>0</spring_stiffness>
          <damping>0</damping>
        </dynamics>
      </axis>
    </joint>

    <link name="cable0">
      <pose>-3.505850 -3.504926 3.504926 -2.356194 0.698478 -1.442379</pose>
      <visual name="visual">
        <geometry>
          <cylinder>
            <radius>0.005</radius>
            <length>11.8368238983</length>
          </cylinder>
        </geometry>
        <material>
          <script>
            <uri>file://media/materials/scripts/kitchen.material</uri>
            <name>Gazebo/Black</name>
          </script>
        </material>
      </visual>
      <inertial>
        <inertia>
          <ixx>0.001</ixx>
          <iyy>0.001</iyy>
          <izz>0.001</izz>
          <ixy>0</ixy>
          <ixz>0</ixz>
          <iyz>0</iyz>
        </inertia>
        <mass>0.001</mass>
      </inertial>
    </link>
    <link name="virt_X0">
      <inertial>
        <inertia>
          <ixx>0.001</ixx>
          <iyy>0.001</iyy>
          <izz>0.001</izz>
          <ixy>0</ixy>
          <ixz>0</ixz>
          <iyz>0</iyz>
        </inertia>
        <mass>0.001</mass>
      </inertial>
      <pose>-3.500000 -3.500000 3.500000 -2.356194 0.698478 -1.442379</pose>
    </link>
    <joint name="rev_X0" type="revolute">
      <pose>0 0 0 -2.356194 0.698478 -1.442379</pose>
      <parent>frame</parent>
      <child>virt_X0</child>
      <axis>
        <xyz>0.098075 -0.759516 -0.643053</xyz>
        <limit>
          <effort>1000</effort>
          <velocity>10</velocity>
        </limit>
        <dynamics>
          <damping>0.01</damping>
        </dynamics>
      </axis>
    </joint>
    <link name="virt_Y0">
      <inertial>
        <inertia>
          <ixx>0.001</ixx>
          <iyy>0.001</iyy>
          <izz>0.001</izz>
          <ixy>0</ixy>
          <ixz>0</ixz>
          <iyz>0</iyz>
        </inertia>
        <mass>0.001</mass>
      </inertial>
      <pose>-3.500000 -3.500000 3.500000 -2.356194 0.698478 -1.442379</pose>
    </link>
    <joint name="rev_Y0" type="revolute">
      <pose>0 0 0 -2.356194 0.698478 -1.442379</pose>
      <parent>virt_X0</parent>
      <child>virt_Y0</child>
      <axis>
        <xyz>-0.759516 0.360407 -0.541518</xyz>
        <limit>
          <effort>1000</effort>
          <velocity>10</velocity>
        </limit>
        <dynamics>
          <damping>0.01</damping>
        </dynamics>
      </axis>
    </joint>
    <joint name="cable0" type="prismatic">
      <pose>0 0 0.009111 -2.356194 0.698478 -1.442379</pose>
      <parent>virt_Y0</parent>
      <child>cable0</child>
      <axis>
        <xyz>-0.643053 -0.541518 0.541518</xyz>
        <limit>
          <lower>-5.91841194916</lower>
          <upper>5.91841194916</upper>
          <effort>10000</effort>
          <velocity>10</velocity>
        </limit>
        <dynamics>
          <damping>1</damping>
        </dynamics>
      </axis>
    </joint>
    <link name="virt_Xpf0">
      <inertial>
        <inertia>
          <ixx>0.001</ixx>
          <iyy>0.001</iyy>
          <izz>0.001</izz>
          <ixy>0</ixy>
          <ixz>0</ixz>
          <iyz>0</iyz>
        </inertia>
        <mass>0.001</mass>
      </inertial>
      <pose>0.300000 -0.300000 0.300000 -2.356194 0.698478 -1.442379</pose>
    </link>
    <joint name="rev_Xpf0" type="revolute">
      <pose>0 0 0 -2.356194 0.698478 -1.442379</pose>
      <parent>platform</parent>
      <child>virt_Xpf0</child>
      <axis>
        <xyz>1 0 0</xyz>
        <limit>
          <effort>1000</effort>
          <velocity>10</velocity>
        </limit>
        <dynamics>
          <damping>0.01</damping>
        </dynamics>
      </axis>
    </joint>
    <link name="virt_Ypf0">
      <inertial>
        <inertia>
          <ixx>0.001</ixx>
          <iyy>0.001</iyy>
          <izz>0.001</izz>
          <ixy>0</ixy>
          <ixz>0</ixz>
          <iyz>0</iyz>
        </inertia>
        <mass>0.001</mass>
      </inertial>
      <pose>0.300000 -0.300000 0.300000 -2.356194 0.698478 -1.442379</pose>
    </link>
    <joint name="rev_Ypf0" type="revolute">
      <pose>0 0 0 -2.356194 0.698478 -1.442379</pose>
      <parent>virt_Xpf0</parent>
      <child>virt_Ypf0</child>
      <axis>
        <xyz>0 1 0</xyz>
        <limit>
          <effort>1000</effort>
          <velocity>10</velocity>
        </limit>
        <dynamics>
          <damping>0.01</damping>
        </dynamics>
      </axis>
    </joint>
    <joint name="rev_Zpf0" type="revolute">
      <pose>0 0 0 -2.356194 0.698478 -1.442379</pose>
      <child>virt_Ypf0</child>
      <parent>cable0</parent>
      <axis>
        <xyz>0 0 1</xyz>
        <limit>
          <effort>1000</effort>
          <velocity>10</velocity>
        </limit>
        <dynamics>
          <damping>0.01</damping>
        </dynamics>
      </axis>
    </joint>
    <link name="cable1">
      <pose>-3.677644 -3.710952 3.644336 -2.170847 0.607359 -1.072165</pose>
      <visual name="visual">
        <geometry>
          <cylinder>
            <radius>0.005</radius>
            <length>11.8368238983</length>
          </cylinder>
        </geometry>
        <material>
          <script>
            <uri>file://media/materials/scripts/kitchen.material</uri>
            <name>Gazebo/Black</name>
          </script>
        </material>
      </visual>
      <inertial>
        <inertia>
          <ixx>0.001</ixx>
          <iyy>0.001</iyy>
          <izz>0.001</izz>
          <ixy>0</ixy>
          <ixz>0</ixz>
          <iyz>0</iyz>
        </inertia>
        <mass>0.001</mass>
      </inertial>
    </link>
    <link name="virt_X1">
      <inertial>
        <inertia>
          <ixx>0.001</ixx>
          <iyy>0.001</iyy>
          <izz>0.001</izz>
          <ixy>0</ixy>
          <ixz>0</ixz>
          <iyz>0</iyz>
        </inertia>
        <mass>0.001</mass>
      </inertial>
      <pose>-3.500000 -3.500000 3.500000 -2.170847 0.607359 -1.072165</pose>
    </link>
    <joint name="rev_X1" type="revolute">
      <pose>0 0 0 -2.170847 0.607359 -1.072165</pose>
      <parent>frame</parent>
      <child>virt_X1</child>
      <axis>
        <xyz>0.392697 -0.721172 -0.570701</xyz>
        <limit>
          <effort>1000</effort>
          <velocity>10</velocity>
        </limit>
        <dynamics>
          <damping>0.01</damping>
        </dynamics>
      </axis>
    </joint>
    <link name="virt_Y1">
      <inertial>
        <inertia>
          <ixx>0.001</ixx>
          <iyy>0.001</iyy>
          <izz>0.001</izz>
          <ixy>0</ixy>
          <ixz>0</ixz>
          <iyz>0</iyz>
        </inertia>
        <mass>0.001</mass>
      </inertial>
      <pose>-3.500000 -3.500000 3.500000 -2.170847 0.607359 -1.072165</pose>
    </link>
    <joint name="rev_Y1" type="revolute">
      <pose>0 0 0 -2.170847 0.607359 -1.072165</pose>
      <parent>virt_X1</parent>
      <child>virt_Y1</child>
      <axis>
        <xyz>-0.721172 0.143608 -0.677708</xyz>
        <limit>
          <effort>1000</effort>
          <velocity>10</velocity>
        </limit>
        <dynamics>
          <damping>0.01</damping>
        </dynamics>
      </axis>
    </joint>
    <joint name="cable1" type="prismatic">
      <pose>0 0 0.328554 -2.170847 0.607359 -1.072165</pose>
      <parent>virt_Y1</parent>
      <child>cable1</child>
      <axis>
        <xyz>-0.570701 -0.677708 0.463695</xyz>
        <limit>
          <lower>-5.91841194916</lower>
          <upper>5.91841194916</upper>
          <effort>10000</effort>
          <velocity>10</velocity>
        </limit>
        <dynamics>
          <damping>1</damping>
        </dynamics>
      </axis>
    </joint>
    <link name="virt_Xpf1">
      <inertial>
        <inertia>
          <ixx>0.001</ixx>
          <iyy>0.001</iyy>
          <izz>0.001</izz>
          <ixy>0</ixy>
          <ixz>0</ixz>
          <iyz>0</iyz>
        </inertia>
        <mass>0.001</mass>
      </inertial>
      <pose>-0.300000 0.300000 0.900000 -2.170847 0.607359 -1.072165</pose>
    </link>
    <joint name="rev_Xpf1" type="revolute">
      <pose>0 0 0 -2.170847 0.607359 -1.072165</pose>
      <parent>platform</parent>
      <child>virt_Xpf1</child>
      <axis>
        <xyz>1 0 0</xyz>
        <limit>
          <effort>1000</effort>
          <velocity>10</velocity>
        </limit>
        <dynamics>
          <damping>0.01</damping>
        </dynamics>
      </axis>
    </joint>
    <link name="virt_Ypf1">
      <inertial>
        <inertia>
          <ixx>0.001</ixx>
          <iyy>0.001</iyy>
          <izz>0.001</izz>
          <ixy>0</ixy>
          <ixz>0</ixz>
          <iyz>0</iyz>
        </inertia>
        <mass>0.001</mass>
      </inertial>
      <pose>-0.300000 0.300000 0.900000 -2.170847 0.607359 -1.072165</pose>
    </link>
    <joint name="rev_Ypf1" type="revolute">
      <pose>0 0 0 -2.170847 0.607359 -1.072165</pose>
      <parent>virt_Xpf1</parent>
      <child>virt_Ypf1</child>
      <axis>
        <xyz>0 1 0</xyz>
        <limit>
          <effort>1000</effort>
          <velocity>10</velocity>
        </limit>
        <dynamics>
          <damping>0.01</damping>
        </dynamics>
      </axis>
    </joint>
    <joint name="rev_Zpf1" type="revolute">
      <pose>0 0 0 -2.170847 0.607359 -1.072165</pose>
      <child>virt_Ypf1</child>
      <parent>cable1</parent>
      <axis>
        <xyz>0 0 1</xyz>
        <limit>
          <effort>1000</effort>
          <velocity>10</velocity>
        </limit>
        <dynamics>
          <damping>0.01</damping>
        </dynamics>
      </axis>
    </joint>
    <link name="cable2">
      <pose>3.710952 -3.677644 3.644336 -2.253113 -0.744641 1.374236</pose>
      <visual name="visual">
        <geometry>
          <cylinder>
            <radius>0.005</radius>
            <length>11.8368238983</length>
          </cylinder>
        </geometry>
        <material>
          <script>
            <uri>file://media/materials/scripts/kitchen.material</uri>
            <name>Gazebo/Black</name>
          </script>
        </material>
      </visual>
      <inertial>
        <inertia>
          <ixx>0.001</ixx>
          <iyy>0.001</iyy>
          <izz>0.001</izz>
          <ixy>0</ixy>
          <ixz>0</ixz>
          <iyz>0</iyz>
        </inertia>
        <mass>0.001</mass>
      </inertial>
    </link>
    <link name="virt_X2">
      <inertial>
        <inertia>
          <ixx>0.001</ixx>
          <iyy>0.001</iyy>
          <izz>0.001</izz>
          <ixy>0</ixy>
          <ixz>0</ixz>
          <iyz>0</iyz>
        </inertia>
        <mass>0.001</mass>
      </inertial>
      <pose>3.500000 -3.500000 3.500000 -2.253113 -0.744641 1.374236</pose>
    </link>
    <joint name="rev_X2" type="revolute">
      <pose>0 0 0 -2.253113 -0.744641 1.374236</pose>
      <parent>frame</parent>
      <child>virt_X2</child>
      <axis>
        <xyz>0.143608 0.721172 0.677708</xyz>
        <limit>
          <effort>1000</effort>
          <velocity>10</velocity>
        </limit>
        <dynamics>
          <damping>0.01</damping>
        </dynamics>
      </axis>
    </joint>
    <link name="virt_Y2">
      <inertial>
        <inertia>
          <ixx>0.001</ixx>
          <iyy>0.001</iyy>
          <izz>0.001</izz>
          <ixy>0</ixy>
          <ixz>0</ixz>
          <iyz>0</iyz>
        </inertia>
        <mass>0.001</mass>
      </inertial>
      <pose>3.500000 -3.500000 3.500000 -2.253113 -0.744641 1.374236</pose>
    </link>
    <joint name="rev_Y2" type="revolute">
      <pose>0 0 0 -2.253113 -0.744641 1.374236</pose>
      <parent>virt_X2</parent>
      <child>virt_Y2</child>
      <axis>
        <xyz>0.721172 0.392697 -0.570701</xyz>
        <limit>
          <effort>1000</effort>
          <velocity>10</velocity>
        </limit>
        <dynamics>
          <damping>0.01</damping>
        </dynamics>
      </axis>
    </joint>
    <joint name="cable2" type="prismatic">
      <pose>0 0 0.328554 -2.253113 -0.744641 1.374236</pose>
      <parent>virt_Y2</parent>
      <child>cable2</child>
      <axis>
        <xyz>0.677708 -0.570701 0.463695</xyz>
        <limit>
          <lower>-5.91841194916</lower>
          <upper>5.91841194916</upper>
          <effort>10000</effort>
          <velocity>10</velocity>
        </limit>
        <dynamics>
          <damping>1</damping>
        </dynamics>
      </axis>
    </joint>
    <link name="virt_Xpf2">
      <inertial>
        <inertia>
          <ixx>0.001</ixx>
          <iyy>0.001</iyy>
          <izz>0.001</izz>
          <ixy>0</ixy>
          <ixz>0</ixz>
          <iyz>0</iyz>
        </inertia>
        <mass>0.001</mass>
      </inertial>
      <pose>-0.300000 -0.300000 0.900000 -2.253113 -0.744641 1.374236</pose>
    </link>
    <joint name="rev_Xpf2" type="revolute">
      <pose>0 0 0 -2.253113 -0.744641 1.374236</pose>
      <parent>platform</parent>
      <child>virt_Xpf2</child>
      <axis>
        <xyz>1 0 0</xyz>
        <limit>
          <effort>1000</effort>
          <velocity>10</velocity>
        </limit>
        <dynamics>
          <damping>0.01</damping>
        </dynamics>
      </axis>
    </joint>
    <link name="virt_Ypf2">
      <inertial>
        <inertia>
          <ixx>0.001</ixx>
          <iyy>0.001</iyy>
          <izz>0.001</izz>
          <ixy>0</ixy>
          <ixz>0</ixz>
          <iyz>0</iyz>
        </inertia>
        <mass>0.001</mass>
      </inertial>
      <pose>-0.300000 -0.300000 0.900000 -2.253113 -0.744641 1.374236</pose>
    </link>
    <joint name="rev_Ypf2" type="revolute">
      <pose>0 0 0 -2.253113 -0.744641 1.374236</pose>
      <parent>virt_Xpf2</parent>
      <child>virt_Ypf2</child>
      <axis>
        <xyz>0 1 0</xyz>
        <limit>
          <effort>1000</effort>
          <velocity>10</velocity>
        </limit>
        <dynamics>
          <damping>0.01</damping>
        </dynamics>
      </axis>
    </joint>
    <joint name="rev_Zpf2" type="revolute">
      <pose>0 0 0 -2.253113 -0.744641 1.374236</pose>
      <child>virt_Ypf2</child>
      <parent>cable2</parent>
      <axis>
        <xyz>0 0 1</xyz>
        <limit>
          <effort>1000</effort>
          <velocity>10</velocity>
        </limit>
        <dynamics>
          <damping>0.01</damping>
        </dynamics>
      </axis>
    </joint>
    <link name="cable3">
      <pose>3.504926 -3.505850 3.504926 -2.270689 -0.572242 1.127738</pose>
      <visual name="visual">
        <geometry>
          <cylinder>
            <radius>0.005</radius>
            <length>11.8368238983</length>
          </cylinder>
        </geometry>
        <material>
          <script>
            <uri>file://media/materials/scripts/kitchen.material</uri>
            <name>Gazebo/Black</name>
          </script>
        </material>
      </visual>
      <inertial>
        <inertia>
          <ixx>0.001</ixx>
          <iyy>0.001</iyy>
          <izz>0.001</izz>
          <ixy>0</ixy>
          <ixz>0</ixz>
          <iyz>0</iyz>
        </inertia>
        <mass>0.001</mass>
      </inertial>
    </link>
    <link name="virt_X3">
      <inertial>
        <inertia>
          <ixx>0.001</ixx>
          <iyy>0.001</iyy>
          <izz>0.001</izz>
          <ixy>0</ixy>
          <ixz>0</ixz>
          <iyz>0</iyz>
        </inertia>
        <mass>0.001</mass>
      </inertial>
      <pose>3.500000 -3.500000 3.500000 -2.270689 -0.572242 1.127738</pose>
    </link>
    <joint name="rev_X3" type="revolute">
      <pose>0 0 0 -2.270689 -0.572242 1.127738</pose>
      <parent>frame</parent>
      <child>virt_X3</child>
      <axis>
        <xyz>0.360407 0.759516 0.541518</xyz>
        <limit>
          <effort>1000</effort>
          <velocity>10</velocity>
        </limit>
        <dynamics>
          <damping>0.01</damping>
        </dynamics>
      </axis>
    </joint>
    <link name="virt_Y3">
      <inertial>
        <inertia>
          <ixx>0.001</ixx>
          <iyy>0.001</iyy>
          <izz>0.001</izz>
          <ixy>0</ixy>
          <ixz>0</ixz>
          <iyz>0</iyz>
        </inertia>
        <mass>0.001</mass>
      </inertial>
      <pose>3.500000 -3.500000 3.500000 -2.270689 -0.572242 1.127738</pose>
    </link>
    <joint name="rev_Y3" type="revolute">
      <pose>0 0 0 -2.270689 -0.572242 1.127738</pose>
      <parent>virt_X3</parent>
      <child>virt_Y3</child>
      <axis>
        <xyz>0.759516 0.098075 -0.643053</xyz>
        <limit>
          <effort>1000</effort>
          <velocity>10</velocity>
        </limit>
        <dynamics>
          <damping>0.01</damping>
        </dynamics>
      </axis>
    </joint>
    <joint name="cable3" type="prismatic">
      <pose>0 0 0.009111 -2.270689 -0.572242 1.127738</pose>
      <parent>virt_Y3</parent>
      <child>cable3</child>
      <axis>
        <xyz>0.541518 -0.643053 0.541518</xyz>
        <limit>
          <lower>-5.91841194916</lower>
          <upper>5.91841194916</upper>
          <effort>10000</effort>
          <velocity>10</velocity>
        </limit>
        <dynamics>
          <damping>1</damping>
        </dynamics>
      </axis>
    </joint>
    <link name="virt_Xpf3">
      <inertial>
        <inertia>
          <ixx>0.001</ixx>
          <iyy>0.001</iyy>
          <izz>0.001</izz>
          <ixy>0</ixy>
          <ixz>0</ixz>
          <iyz>0</iyz>
        </inertia>
        <mass>0.001</mass>
      </inertial>
      <pose>0.300000 0.300000 0.300000 -2.270689 -0.572242 1.127738</pose>
    </link>
    <joint name="rev_Xpf3" type="revolute">
      <pose>0 0 0 -2.270689 -0.572242 1.127738</pose>
      <parent>platform</parent>
      <child>virt_Xpf3</child>
      <axis>
        <xyz>1 0 0</xyz>
        <limit>
          <effort>1000</effort>
          <velocity>10</velocity>
        </limit>
        <dynamics>
          <damping>0.01</damping>
        </dynamics>
      </axis>
    </joint>
    <link name="virt_Ypf3">
      <inertial>
        <inertia>
          <ixx>0.001</ixx>
          <iyy>0.001</iyy>
          <izz>0.001</izz>
          <ixy>0</ixy>
          <ixz>0</ixz>
          <iyz>0</iyz>
        </inertia>
        <mass>0.001</mass>
      </inertial>
      <pose>0.300000 0.300000 0.300000 -2.270689 -0.572242 1.127738</pose>
    </link>
    <joint name="rev_Ypf3" type="revolute">
      <pose>0 0 0 -2.270689 -0.572242 1.127738</pose>
      <parent>virt_Xpf3</parent>
      <child>virt_Ypf3</child>
      <axis>
        <xyz>0 1 0</xyz>
        <limit>
          <effort>1000</effort>
          <velocity>10</velocity>
        </limit>
        <dynamics>
          <damping>0.01</damping>
        </dynamics>
      </axis>
    </joint>
    <joint name="rev_Zpf3" type="revolute">
      <pose>0 0 0 -2.270689 -0.572242 1.127738</pose>
      <child>virt_Ypf3</child>
      <parent>cable3</parent>
      <axis>
        <xyz>0 0 1</xyz>
        <limit>
          <effort>1000</effort>
          <velocity>10</velocity>
        </limit>
        <dynamics>
          <damping>0.01</damping>
        </dynamics>
      </axis>
    </joint>
    <link name="cable4">
      <pose>-3.504926 3.505850 3.504926 2.270689 0.572242 1.127738</pose>
      <visual name="visual">
        <geometry>
          <cylinder>
            <radius>0.005</radius>
            <length>11.8368238983</length>
          </cylinder>
        </geometry>
        <material>
          <script>
            <uri>file://media/materials/scripts/kitchen.material</uri>
            <name>Gazebo/Black</name>
          </script>
        </material>
      </visual>
      <inertial>
        <inertia>
          <ixx>0.001</ixx>
          <iyy>0.001</iyy>
          <izz>0.001</izz>
          <ixy>0</ixy>
          <ixz>0</ixz>
          <iyz>0</iyz>
        </inertia>
        <mass>0.001</mass>
      </inertial>
    </link>
    <link name="virt_X4">
      <inertial>
        <inertia>
          <ixx>0.001</ixx>
          <iyy>0.001</iyy>
          <izz>0.001</izz>
          <ixy>0</ixy>
          <ixz>0</ixz>
          <iyz>0</iyz>
        </inertia>
        <mass>0.001</mass>
      </inertial>
      <pose>-3.500000 3.500000 3.500000 2.270689 0.572242 1.127738</pose>
    </link>
    <joint name="rev_X4" type="revolute">
      <pose>0 0 0 2.270689 0.572242 1.127738</pose>
      <parent>frame</parent>
      <child>virt_X4</child>
      <axis>
        <xyz>0.360407 0.759516 -0.541518</xyz>
        <limit>
          <effort>1000</effort>
          <velocity>10</velocity>
        </limit>
        <dynamics>
          <damping>0.01</damping>
        </dynamics>
      </axis>
    </joint>
    <link name="virt_Y4">
      <inertial>
        <inertia>
          <ixx>0.001</ixx>
          <iyy>0.001</iyy>
          <izz>0.001</izz>
          <ixy>0</ixy>
          <ixz>0</ixz>
          <iyz>0</iyz>
        </inertia>
        <mass>0.001</mass>
      </inertial>
      <pose>-3.500000 3.500000 3.500000 2.270689 0.572242 1.127738</pose>
    </link>
    <joint name="rev_Y4" type="revolute">
      <pose>0 0 0 2.270689 0.572242 1.127738</pose>
      <parent>virt_X4</parent>
      <child>virt_Y4</child>
      <axis>
        <xyz>0.759516 0.098075 0.643053</xyz>
        <limit>
          <effort>1000</effort>
          <velocity>10</velocity>
        </limit>
        <dynamics>
          <damping>0.01</damping>
        </dynamics>
      </axis>
    </joint>
    <joint name="cable4" type="prismatic">
      <pose>0 0 0.009111 2.270689 0.572242 1.127738</pose>
      <parent>virt_Y4</parent>
      <child>cable4</child>
      <axis>
        <xyz>-0.541518 0.643053 0.541518</xyz>
        <limit>
          <lower>-5.91841194916</lower>
          <upper>5.91841194916</upper>
          <effort>10000</effort>
          <velocity>10</velocity>
        </limit>
        <dynamics>
          <damping>1</damping>
        </dynamics>
      </axis>
    </joint>
    <link name="virt_Xpf4">
      <inertial>
        <inertia>
          <ixx>0.001</ixx>
          <iyy>0.001</iyy>
          <izz>0.001</izz>
          <ixy>0</ixy>
          <ixz>0</ixz>
          <iyz>0</iyz>
        </inertia>
        <mass>0.001</mass>
      </inertial>
      <pose>-0.300000 -0.300000 0.300000 2.270689 0.572242 1.127738</pose>
    </link>
    <joint name="rev_Xpf4" type="revolute">
      <pose>0 0 0 2.270689 0.572242 1.127738</pose>
      <parent>platform</parent>
      <child>virt_Xpf4</child>
      <axis>
        <xyz>1 0 0</xyz>
        <limit>
          <effort>1000</effort>
          <velocity>10</velocity>
        </limit>
        <dynamics>
          <damping>0.01</damping>
        </dynamics>
      </axis>
    </joint>
    <link name="virt_Ypf4">
      <inertial>
        <inertia>
          <ixx>0.001</ixx>
          <iyy>0.001</iyy>
          <izz>0.001</izz>
          <ixy>0</ixy>
          <ixz>0</ixz>
          <iyz>0</iyz>
        </inertia>
        <mass>0.001</mass>
      </inertial>
      <pose>-0.300000 -0.300000 0.300000 2.270689 0.572242 1.127738</pose>
    </link>
    <joint name="rev_Ypf4" type="revolute">
      <pose>0 0 0 2.270689 0.572242 1.127738</pose>
      <parent>virt_Xpf4</parent>
      <child>virt_Ypf4</child>
      <axis>
        <xyz>0 1 0</xyz>
        <limit>
          <effort>1000</effort>
          <velocity>10</velocity>
        </limit>
        <dynamics>
          <damping>0.01</damping>
        </dynamics>
      </axis>
    </joint>
    <joint name="rev_Zpf4" type="revolute">
      <pose>0 0 0 2.270689 0.572242 1.127738</pose>
      <child>virt_Ypf4</child>
      <parent>cable4</parent>
      <axis>
        <xyz>0 0 1</xyz>
        <limit>
          <effort>1000</effort>
          <velocity>10</velocity>
        </limit>
        <dynamics>
          <damping>0.01</damping>
        </dynamics>
      </axis>
    </joint>
    <link name="cable5">
      <pose>-3.710952 3.677644 3.644336 2.253113 0.744641 1.374236</pose>
      <visual name="visual">
        <geometry>
          <cylinder>
            <radius>0.005</radius>
            <length>11.8368238983</length>
          </cylinder>
        </geometry>
        <material>
          <script>
            <uri>file://media/materials/scripts/kitchen.material</uri>
            <name>Gazebo/Black</name>
          </script>
        </material>
      </visual>
      <inertial>
        <inertia>
          <ixx>0.001</ixx>
          <iyy>0.001</iyy>
          <izz>0.001</izz>
          <ixy>0</ixy>
          <ixz>0</ixz>
          <iyz>0</iyz>
        </inertia>
        <mass>0.001</mass>
      </inertial>
    </link>
    <link name="virt_X5">
      <inertial>
        <inertia>
          <ixx>0.001</ixx>
          <iyy>0.001</iyy>
          <izz>0.001</izz>
          <ixy>0</ixy>
          <ixz>0</ixz>
          <iyz>0</iyz>
        </inertia>
        <mass>0.001</mass>
      </inertial>
      <pose>-3.500000 3.500000 3.500000 2.253113 0.744641 1.374236</pose>
    </link>
    <joint name="rev_X5" type="revolute">
      <pose>0 0 0 2.253113 0.744641 1.374236</pose>
      <parent>frame</parent>
      <child>virt_X5</child>
      <axis>
        <xyz>0.143608 0.721172 -0.677708</xyz>
        <limit>
          <effort>1000</effort>
          <velocity>10</velocity>
        </limit>
        <dynamics>
          <damping>0.01</damping>
        </dynamics>
      </axis>
    </joint>
    <link name="virt_Y5">
      <inertial>
        <inertia>
          <ixx>0.001</ixx>
          <iyy>0.001</iyy>
          <izz>0.001</izz>
          <ixy>0</ixy>
          <ixz>0</ixz>
          <iyz>0</iyz>
        </inertia>
        <mass>0.001</mass>
      </inertial>
      <pose>-3.500000 3.500000 3.500000 2.253113 0.744641 1.374236</pose>
    </link>
    <joint name="rev_Y5" type="revolute">
      <pose>0 0 0 2.253113 0.744641 1.374236</pose>
      <parent>virt_X5</parent>
      <child>virt_Y5</child>
      <axis>
        <xyz>0.721172 0.392697 0.570701</xyz>
        <limit>
          <effort>1000</effort>
          <velocity>10</velocity>
        </limit>
        <dynamics>
          <damping>0.01</damping>
        </dynamics>
      </axis>
    </joint>
    <joint name="cable5" type="prismatic">
      <pose>0 0 0.328554 2.253113 0.744641 1.374236</pose>
      <parent>virt_Y5</parent>
      <child>cable5</child>
      <axis>
        <xyz>-0.677708 0.570701 0.463695</xyz>
        <limit>
          <lower>-5.91841194916</lower>
          <upper>5.91841194916</upper>
          <effort>10000</effort>
          <velocity>10</velocity>
        </limit>
        <dynamics>
          <damping>1</damping>
        </dynamics>
      </axis>
    </joint>
    <link name="virt_Xpf5">
      <inertial>
        <inertia>
          <ixx>0.001</ixx>
          <iyy>0.001</iyy>
          <izz>0.001</izz>
          <ixy>0</ixy>
          <ixz>0</ixz>
          <iyz>0</iyz>
        </inertia>
        <mass>0.001</mass>
      </inertial>
      <pose>0.300000 0.300000 0.900000 2.253113 0.744641 1.374236</pose>
    </link>
    <joint name="rev_Xpf5" type="revolute">
      <pose>0 0 0 2.253113 0.744641 1.374236</pose>
      <parent>platform</parent>
      <child>virt_Xpf5</child>
      <axis>
        <xyz>1 0 0</xyz>
        <limit>
          <effort>1000</effort>
          <velocity>10</velocity>
        </limit>
        <dynamics>
          <damping>0.01</damping>
        </dynamics>
      </axis>
    </joint>
    <link name="virt_Ypf5">
      <inertial>
        <inertia>
          <ixx>0.001</ixx>
          <iyy>0.001</iyy>
          <izz>0.001</izz>
          <ixy>0</ixy>
          <ixz>0</ixz>
          <iyz>0</iyz>
        </inertia>
        <mass>0.001</mass>
      </inertial>
      <pose>0.300000 0.300000 0.900000 2.253113 0.744641 1.374236</pose>
    </link>
    <joint name="rev_Ypf5" type="revolute">
      <pose>0 0 0 2.253113 0.744641 1.374236</pose>
      <parent>virt_Xpf5</parent>
      <child>virt_Ypf5</child>
      <axis>
        <xyz>0 1 0</xyz>
        <limit>
          <effort>1000</effort>
          <velocity>10</velocity>
        </limit>
        <dynamics>
          <damping>0.01</damping>
        </dynamics>
      </axis>
    </joint>
    <joint name="rev_Zpf5" type="revolute">
      <pose>0 0 0 2.253113 0.744641 1.374236</pose>
      <child>virt_Ypf5</child>
      <parent>cable5</parent>
      <axis>
        <xyz>0 0 1</xyz>
        <limit>
          <effort>1000</effort>
          <velocity>10</velocity>
        </limit>
        <dynamics>
          <damping>0.01</damping>
        </dynamics>
      </axis>
    </joint>
    <link name="cable6">
      <pose>3.677644 3.710952 3.644336 2.170847 -0.607359 -1.072165</pose>
      <visual name="visual">
        <geometry>
          <cylinder>
            <radius>0.005</radius>
            <length>11.8368238983</length>
          </cylinder>
        </geometry>
        <material>
          <script>
            <uri>file://media/materials/scripts/kitchen.material</uri>
            <name>Gazebo/Black</name>
          </script>
        </material>
      </visual>
      <inertial>
        <inertia>
          <ixx>0.001</ixx>
          <iyy>0.001</iyy>
          <izz>0.001</izz>
          <ixy>0</ixy>
          <ixz>0</ixz>
          <iyz>0</iyz>
        </inertia>
        <mass>0.001</mass>
      </inertial>
    </link>
    <link name="virt_X6">
      <inertial>
        <inertia>
          <ixx>0.001</ixx>
          <iyy>0.001</iyy>
          <izz>0.001</izz>
          <ixy>0</ixy>
          <ixz>0</ixz>
          <iyz>0</iyz>
        </inertia>
        <mass>0.001</mass>
      </inertial>
      <pose>3.500000 3.500000 3.500000 2.170847 -0.607359 -1.072165</pose>
    </link>
    <joint name="rev_X6" type="revolute">
      <pose>0 0 0 2.170847 -0.607359 -1.072165</pose>
      <parent>frame</parent>
      <child>virt_X6</child>
      <axis>
        <xyz>0.392697 -0.721172 0.570701</xyz>
        <limit>
          <effort>1000</effort>
          <velocity>10</velocity>
        </limit>
        <dynamics>
          <damping>0.01</damping>
        </dynamics>
      </axis>
    </joint>
    <link name="virt_Y6">
      <inertial>
        <inertia>
          <ixx>0.001</ixx>
          <iyy>0.001</iyy>
          <izz>0.001</izz>
          <ixy>0</ixy>
          <ixz>0</ixz>
          <iyz>0</iyz>
        </inertia>
        <mass>0.001</mass>
      </inertial>
      <pose>3.500000 3.500000 3.500000 2.170847 -0.607359 -1.072165</pose>
    </link>
    <joint name="rev_Y6" type="revolute">
      <pose>0 0 0 2.170847 -0.607359 -1.072165</pose>
      <parent>virt_X6</parent>
      <child>virt_Y6</child>
      <axis>
        <xyz>-0.721172 0.143608 0.677708</xyz>
        <limit>
          <effort>1000</effort>
          <velocity>10</velocity>
        </limit>
        <dynamics>
          <damping>0.01</damping>
        </dynamics>
      </axis>
    </joint>
    <joint name="cable6" type="prismatic">
      <pose>0 0 0.328554 2.170847 -0.607359 -1.072165</pose>
      <parent>virt_Y6</parent>
      <child>cable6</child>
      <axis>
        <xyz>0.570701 0.677708 0.463695</xyz>
        <limit>
          <lower>-5.91841194916</lower>
          <upper>5.91841194916</upper>
          <effort>10000</effort>
          <velocity>10</velocity>
        </limit>
        <dynamics>
          <damping>1</damping>
        </dynamics>
      </axis>
    </joint>
    <link name="virt_Xpf6">
      <inertial>
        <inertia>
          <ixx>0.001</ixx>
          <iyy>0.001</iyy>
          <izz>0.001</izz>
          <ixy>0</ixy>
          <ixz>0</ixz>
          <iyz>0</iyz>
        </inertia>
        <mass>0.001</mass>
      </inertial>
      <pose>0.300000 -0.300000 0.900000 2.170847 -0.607359 -1.072165</pose>
    </link>
    <joint name="rev_Xpf6" type="revolute">
      <pose>0 0 0 2.170847 -0.607359 -1.072165</pose>
      <parent>platform</parent>
      <child>virt_Xpf6</child>
      <axis>
        <xyz>1 0 0</xyz>
        <limit>
          <effort>1000</effort>
          <velocity>10</velocity>
        </limit>
        <dynamics>
          <damping>0.01</damping>
        </dynamics>
      </axis>
    </joint>
    <link name="virt_Ypf6">
      <inertial>
        <inertia>
          <ixx>0.001</ixx>
          <iyy>0.001</iyy>
          <izz>0.001</izz>
          <ixy>0</ixy>
          <ixz>0</ixz>
          <iyz>0</iyz>
        </inertia>
        <mass>0.001</mass>
      </inertial>
      <pose>0.300000 -0.300000 0.900000 2.170847 -0.607359 -1.072165</pose>
    </link>
    <joint name="rev_Ypf6" type="revolute">
      <pose>0 0 0 2.170847 -0.607359 -1.072165</pose>
      <parent>virt_Xpf6</parent>
      <child>virt_Ypf6</child>
      <axis>
        <xyz>0 1 0</xyz>
        <limit>
          <effort>1000</effort>
          <velocity>10</velocity>
        </limit>
        <dynamics>
          <damping>0.01</damping>
        </dynamics>
      </axis>
    </joint>
    <joint name="rev_Zpf6" type="revolute">
      <pose>0 0 0 2.170847 -0.607359 -1.072165</pose>
      <child>virt_Ypf6</child>
      <parent>cable6</parent>
      <axis>
        <xyz>0 0 1</xyz>
        <limit>
          <effort>1000</effort>
          <velocity>10</velocity>
        </limit>
        <dynamics>
          <damping>0.01</damping>
        </dynamics>
      </axis>
    </joint>
    <link name="cable7">
      <pose>3.505850 3.504926 3.504926 2.356194 -0.698478 -1.442379</pose>
      <visual name="visual">
        <geometry>
          <cylinder>
            <radius>0.005</radius>
            <length>11.8368238983</length>
          </cylinder>
        </geometry>
        <material>
          <script>
            <uri>file://media/materials/scripts/kitchen.material</uri>
            <name>Gazebo/Black</name>
          </script>
        </material>
      </visual>
      <inertial>
        <inertia>
          <ixx>0.001</ixx>
          <iyy>0.001</iyy>
          <izz>0.001</izz>
          <ixy>0</ixy>
          <ixz>0</ixz>
          <iyz>0</iyz>
        </inertia>
        <mass>0.001</mass>
      </inertial>
    </link>
    <link name="virt_X7">
      <inertial>
        <inertia>
          <ixx>0.001</ixx>
          <iyy>0.001</iyy>
          <izz>0.001</izz>
          <ixy>0</ixy>
          <ixz>0</ixz>
          <iyz>0</iyz>
        </inertia>
        <mass>0.001</mass>
      </inertial>
      <pose>3.500000 3.500000 3.500000 2.356194 -0.698478 -1.442379</pose>
    </link>
    <joint name="rev_X7" type="revolute">
      <pose>0 0 0 2.356194 -0.698478 -1.442379</pose>
      <parent>frame</parent>
      <child>virt_X7</child>
      <axis>
        <xyz>0.098075 -0.759516 0.643053</xyz>
        <limit>
          <effort>1000</effort>
          <velocity>10</velocity>
        </limit>
        <dynamics>
          <damping>0.01</damping>
        </dynamics>
      </axis>
    </joint>
    <link name="virt_Y7">
      <inertial>
        <inertia>
          <ixx>0.001</ixx>
          <iyy>0.001</iyy>
          <izz>0.001</izz>
          <ixy>0</ixy>
          <ixz>0</ixz>
          <iyz>0</iyz>
        </inertia>
        <mass>0.001</mass>
      </inertial>
      <pose>3.500000 3.500000 3.500000 2.356194 -0.698478 -1.442379</pose>
    </link>
    <joint name="rev_Y7" type="revolute">
      <pose>0 0 0 2.356194 -0.698478 -1.442379</pose>
      <parent>virt_X7</parent>
      <child>virt_Y7</child>
      <axis>
        <xyz>-0.759516 0.360407 0.541518</xyz>
        <limit>
          <effort>1000</effort>
          <velocity>10</velocity>
        </limit>
        <dynamics>
          <damping>0.01</damping>
        </dynamics>
      </axis>
    </joint>
    <joint name="cable7" type="prismatic">
      <pose>0 0 0.009111 2.356194 -0.698478 -1.442379</pose>
      <parent>virt_Y7</parent>
      <child>cable7</child>
      <axis>
        <xyz>0.643053 0.541518 0.541518</xyz>
        <limit>
          <lower>-5.91841194916</lower>
          <upper>5.91841194916</upper>
          <effort>10000</effort>
          <velocity>10</velocity>
        </limit>
        <dynamics>
          <damping>1</damping>
        </dynamics>
      </axis>
    </joint>
    <link name="virt_Xpf7">
      <inertial>
        <inertia>
          <ixx>0.001</ixx>
          <iyy>0.001</iyy>
          <izz>0.001</izz>
          <ixy>0</ixy>
          <ixz>0</ixz>
          <iyz>0</iyz>
        </inertia>
        <mass>0.001</mass>
      </inertial>
      <pose>-0.300000 0.300000 0.300000 2.356194 -0.698478 -1.442379</pose>
    </link>
    <joint name="rev_Xpf7" type="revolute">
      <pose>0 0 0 2.356194 -0.698478 -1.442379</pose>
      <parent>platform</parent>
      <child>virt_Xpf7</child>
      <axis>
        <xyz>1 0 0</xyz>
        <limit>
          <effort>1000</effort>
          <velocity>10</velocity>
        </limit>
        <dynamics>
          <damping>0.01</damping>
        </dynamics>
      </axis>
    </joint>
    <link name="virt_Ypf7">
      <inertial>
        <inertia>
          <ixx>0.001</ixx>
          <iyy>0.001</iyy>
          <izz>0.001</izz>
          <ixy>0</ixy>
          <ixz>0</ixz>
          <iyz>0</iyz>
        </inertia>
        <mass>0.001</mass>
      </inertial>
      <pose>-0.300000 0.300000 0.300000 2.356194 -0.698478 -1.442379</pose>
    </link>
    <joint name="rev_Ypf7" type="revolute">
      <pose>0 0 0 2.356194 -0.698478 -1.442379</pose>
      <parent>virt_Xpf7</parent>
      <child>virt_Ypf7</child>
      <axis>
        <xyz>0 1 0</xyz>
        <limit>
          <effort>1000</effort>
          <velocity>10</velocity>
        </limit>
        <dynamics>
          <damping>0.01</damping>
        </dynamics>
      </axis>
    </joint>
    <joint name="rev_Zpf7" type="revolute">
      <pose>0 0 0 2.356194 -0.698478 -1.442379</pose>
      <child>virt_Ypf7</child>
      <parent>cable7</parent>
      <axis>
        <xyz>0 0 1</xyz>
        <limit>
          <effort>1000</effort>
          <velocity>10</velocity>
        </limit>
        <dynamics>
          <damping>0.01</damping>
        </dynamics>
      </axis>
    </joint>
    <plugin filename="libcdpr_plugin.so" name="cdpr_plugin"/>
  </model>
</sdf>
